Failure # 1 (occurred at 2024-03-14_10-24-23)
The actor died because of an error raised in its creation task, [36mray::PPO.__init__()[39m (pid=36414, ip=192.168.1.195, actor_id=279840ae07231a813a7f277601000000, repr=PPO)
  File "/home/ia/.local/lib/python3.8/site-packages/ray/rllib/evaluation/worker_set.py", line 227, in _setup
    self.add_workers(
  File "/home/ia/.local/lib/python3.8/site-packages/ray/rllib/evaluation/worker_set.py", line 593, in add_workers
    raise result.get()
  File "/home/ia/.local/lib/python3.8/site-packages/ray/rllib/utils/actor_manager.py", line 481, in __fetch_result
    result = ray.get(r)
ray.exceptions.RayActorError: The actor died because of an error raised in its creation task, [36mray::RolloutWorker.__init__()[39m (pid=36543, ip=192.168.1.195, actor_id=a30d1fe3f26c4872b0a56bfc01000000, repr=<ray.rllib.evaluation.rollout_worker.RolloutWorker object at 0x7fe3a185bca0>)
TypeError: reset() got an unexpected keyword argument 'seed'

During handling of the above exception, another exception occurred:

[36mray::RolloutWorker.__init__()[39m (pid=36543, ip=192.168.1.195, actor_id=a30d1fe3f26c4872b0a56bfc01000000, repr=<ray.rllib.evaluation.rollout_worker.RolloutWorker object at 0x7fe3a185bca0>)
  File "/home/ia/.local/lib/python3.8/site-packages/ray/rllib/evaluation/rollout_worker.py", line 397, in __init__
    self.env = env_creator(copy.deepcopy(self.env_context))
  File "/home/ia/.local/lib/python3.8/site-packages/ray/rllib/env/utils.py", line 166, in _gym_env_creator
    obs_and_infos = env.reset(seed=None, options={})
  File "/home/ia/.local/lib/python3.8/site-packages/gymnasium/wrappers/compatibility.py", line 100, in reset
    return self.env.reset(), {}
  File "/home/ia/Desktop/DRL_platform/DRL_platform_montpellier/Scenarios/UUV_Mono_Agent_TSP/env.py", line 61, in reset
    observation = self.utils._get_observation(self)
  File "/home/ia/Desktop/DRL_platform/DRL_platform_montpellier/Scenarios/UUV_Mono_Agent_TSP/utils_env.py", line 94, in _get_observation
    obs.append(Env_self.agent.get_battery())
AttributeError: 'UUV' object has no attribute 'get_battery'

During handling of the above exception, another exception occurred:

[36mray::PPO.__init__()[39m (pid=36414, ip=192.168.1.195, actor_id=279840ae07231a813a7f277601000000, repr=PPO)
  File "/home/ia/.local/lib/python3.8/site-packages/ray/rllib/algorithms/algorithm.py", line 517, in __init__
    super().__init__(
  File "/home/ia/.local/lib/python3.8/site-packages/ray/tune/trainable/trainable.py", line 161, in __init__
    self.setup(copy.deepcopy(self.config))
  File "/home/ia/.local/lib/python3.8/site-packages/ray/rllib/algorithms/algorithm.py", line 639, in setup
    self.workers = WorkerSet(
  File "/home/ia/.local/lib/python3.8/site-packages/ray/rllib/evaluation/worker_set.py", line 179, in __init__
    raise e.args[0].args[2]
AttributeError: 'UUV' object has no attribute 'get_battery'
